<?xml version="1.0"?>
<robot name="diff_robot" xmlns:xacro="http://ros.org/wiki/xacro">
  <xacro:include filename="$(find my_ugv_description)/urdf/simple_diff_robot_gazebo.xacro"/>

  <link name="base_footprint"/>

  <joint name="base_joint" type="fixed">
    <parent link="base_footprint"/>
    <child link="base_link"/>
    <origin xyz="0 0 0.01" rpy="0 0 0"/>
  </joint>

  <link name="base_link"> <!-- Important: Every visual, collision and inertial tag has its own origin -->
    <visual>
      <origin xyz="-0.03 0 0.015" rpy="0 0 0"/>
      <geometry>
        <box size="0.14 0.14 0.03" />
      </geometry>
    </visual>

    <collision>
      <origin xyz="-0.03 0 0.015" rpy="0 0 0"/>
      <geometry>
        <box size="0.140 0.140 0.03"/>
      </geometry>
    </collision>

    <inertial>
      <origin xyz="0 0 0.015" rpy="0 0 0"/> <!-- Since a plugin is used, an offset along its X axis can affect the robot behavior -->
      <mass value="8.25e-01"/>
      <inertia ixx="1.4e-03" ixy="0" ixz="0"
               iyy="1.4e-03" iyz="0"
               izz="2.695e-03" />
    </inertial>
  </link>

  <!-- Wheels definition (joints and links) -->
  <joint name="wheel_left_joint" type="continuous">
    <parent link="base_link"/>
    <child link="wheel_left_link"/>
    <origin xyz="0 0.08 0.023" rpy="-1.57 0 0"/>
    <axis xyz="0 0 1"/>
  </joint>

  <link name="wheel_left_link">
    <visual>
      <origin xyz="0 0 0" rpy="0 0 0"/>
      <geometry>
        <cylinder length="0.018" radius="0.033"/>
      </geometry>
    </visual>

    <collision>
      <origin xyz="0 0 0" rpy="0 0 0"/>
      <geometry>
        <cylinder length="0.018" radius="0.033"/>
      </geometry>
    </collision>

    <inertial>
      <origin xyz="0 0 0" />
      <mass value="3e-02" />
      <inertia ixx="9e-06" ixy="0" ixz="0"
               iyy="9e-06" iyz="0"
               izz="1.6e-05" />
      </inertial>
  </link>

  <joint name="wheel_right_joint" type="continuous">
    <parent link="base_link"/>
    <child link="wheel_right_link"/>
    <origin xyz="0 -0.08 0.023" rpy="-1.57 0 0"/>
    <axis xyz="0 0 1"/>
  </joint>

  <link name="wheel_right_link">
    <visual>
      <origin xyz="0 0 0" rpy="0 0 0"/>
      <geometry>
        <cylinder length="0.018" radius="0.033"/>
      </geometry>
    </visual>

    <collision>
      <origin xyz="0 0 0" rpy="0 0 0"/>
      <geometry>
        <cylinder length="0.018" radius="0.033"/>
      </geometry>
    </collision>

    <inertial>
      <origin xyz="0 0 0" />
      <mass value="3e-02" />
      <inertia ixx="9e-06" ixy="0" ixz="0"
               iyy="9e-06" iyz="0"
               izz="1.6e-05" />
      </inertial>
  </link>

  <!-- Caster wheel definition (joint and link) -->
  <joint name="caster_joint" type="fixed">
    <parent link="base_link"/>
    <child link="caster_link"/>
    <origin xyz="-0.08 0 0" rpy="0 0 0"/>
  </joint>

  <link name="caster_link">
    <visual>
      <origin xyz="0 0 0" rpy="0 0 0"/>
      <geometry>
        <sphere radius="0.01"/>
      </geometry>
    </visual>
    
    <collision>
      <origin xyz="0 0 0" rpy="0 0 0"/>
      <geometry>
        <sphere radius="0.01"/>
      </geometry>
    </collision>
    <!-- Since the caster wheel is only a point of contact, inertial tag can be ommited -->
  </link>

</robot>
